09/26/24 20:21:40       Matched 3.0 haridev@corona240.llnl.gov <192.168.64.240:44357?addrs=192.168.64.240-44357&alias=corona240.llnl.gov&noUDP&sock=schedd_2725024_034b> preempting none <192.168.64.240:44357?addrs=192.168.64.240-44357&alias=corona240.llnl.gov&noUDP&sock=startd_2725024_034b> slot1@corona240.llnl.gov
09/26/24 20:38:55       Matched 8.0 haridev@corona198.llnl.gov <192.168.64.198:41823?addrs=192.168.64.198-41823&alias=corona198.llnl.gov&noUDP&sock=schedd_1623342_7b13> preempting none <192.168.64.198:41823?addrs=192.168.64.198-41823&alias=corona198.llnl.gov&noUDP&sock=startd_1623342_7b13> slot1@corona198.llnl.gov
09/26/24 20:48:07       Matched 12.0 haridev@corona198.llnl.gov <192.168.64.198:41823?addrs=192.168.64.198-41823&alias=corona198.llnl.gov&noUDP&sock=schedd_1623342_7b13> preempting none <192.168.64.198:41823?addrs=192.168.64.198-41823&alias=corona198.llnl.gov&noUDP&sock=startd_1623342_7b13> slot1@corona198.llnl.gov
09/26/24 20:50:10       Matched 15.0 haridev@corona198.llnl.gov <192.168.64.198:41823?addrs=192.168.64.198-41823&alias=corona198.llnl.gov&noUDP&sock=schedd_1623342_7b13> preempting none <192.168.64.198:41823?addrs=192.168.64.198-41823&alias=corona198.llnl.gov&noUDP&sock=startd_1623342_7b13> slot1@corona198.llnl.gov
09/26/24 20:51:50       Matched 18.0 haridev@corona198.llnl.gov <192.168.64.198:41823?addrs=192.168.64.198-41823&alias=corona198.llnl.gov&noUDP&sock=schedd_1623342_7b13> preempting none <192.168.64.198:41823?addrs=192.168.64.198-41823&alias=corona198.llnl.gov&noUDP&sock=startd_1623342_7b13> slot1@corona198.llnl.gov
09/26/24 20:53:30       Matched 21.0 haridev@corona198.llnl.gov <192.168.64.198:41823?addrs=192.168.64.198-41823&alias=corona198.llnl.gov&noUDP&sock=schedd_1623342_7b13> preempting none <192.168.64.198:41823?addrs=192.168.64.198-41823&alias=corona198.llnl.gov&noUDP&sock=startd_1623342_7b13> slot1@corona198.llnl.gov
09/26/24 21:21:01       Matched 27.0 haridev@corona198.llnl.gov <192.168.64.198:46405?addrs=192.168.64.198-46405&alias=corona198.llnl.gov&noUDP&sock=schedd_1720673_737c> preempting none <192.168.64.198:46405?addrs=192.168.64.198-46405&alias=corona198.llnl.gov&noUDP&sock=startd_1720673_737c> slot1@corona198.llnl.gov
09/26/24 21:32:33       Matched 33.0 haridev@corona198.llnl.gov <192.168.64.198:39145?addrs=192.168.64.198-39145&alias=corona198.llnl.gov&noUDP&sock=schedd_1726655_9b05> preempting none <192.168.64.198:39145?addrs=192.168.64.198-39145&alias=corona198.llnl.gov&noUDP&sock=startd_1726655_9b05> slot1@corona198.llnl.gov
09/26/24 21:41:25       Matched 37.0 haridev@corona198.llnl.gov <192.168.64.198:39145?addrs=192.168.64.198-39145&alias=corona198.llnl.gov&noUDP&sock=schedd_1726655_9b05> preempting none <192.168.64.198:39145?addrs=192.168.64.198-39145&alias=corona198.llnl.gov&noUDP&sock=startd_1726655_9b05> slot1@corona198.llnl.gov
09/26/24 21:55:37       Matched 39.0 haridev@corona202.llnl.gov <192.168.64.202:37619?addrs=192.168.64.202-37619&alias=corona202.llnl.gov&noUDP&sock=schedd_2583824_8eb0> preempting none <192.168.64.202:37619?addrs=192.168.64.202-37619&alias=corona202.llnl.gov&noUDP&sock=startd_2583824_8eb0> slot1@corona202.llnl.gov
09/26/24 22:01:53       Matched 42.0 haridev@corona202.llnl.gov <192.168.64.202:43025?addrs=192.168.64.202-43025&alias=corona202.llnl.gov&noUDP&sock=schedd_2588031_e537> preempting none <192.168.64.202:43025?addrs=192.168.64.202-43025&alias=corona202.llnl.gov&noUDP&sock=startd_2588031_e537> slot1@corona202.llnl.gov
09/26/24 22:10:30       Matched 46.0 haridev@corona202.llnl.gov <192.168.64.202:43025?addrs=192.168.64.202-43025&alias=corona202.llnl.gov&noUDP&sock=schedd_2588031_e537> preempting none <192.168.64.202:43025?addrs=192.168.64.202-43025&alias=corona202.llnl.gov&noUDP&sock=startd_2588031_e537> slot1@corona202.llnl.gov
09/26/24 23:02:18       Matched 53.0 haridev@corona198.llnl.gov <192.168.64.198:34199?addrs=192.168.64.198-34199&alias=corona198.llnl.gov&noUDP&sock=schedd_1759196_0660> preempting none <192.168.64.198:34199?addrs=192.168.64.198-34199&alias=corona198.llnl.gov&noUDP&sock=startd_1759196_0660> slot1@corona198.llnl.gov
09/26/24 23:11:00       Matched 57.0 haridev@corona198.llnl.gov <192.168.64.198:34199?addrs=192.168.64.198-34199&alias=corona198.llnl.gov&noUDP&sock=schedd_1759196_0660> preempting none <192.168.64.198:34199?addrs=192.168.64.198-34199&alias=corona198.llnl.gov&noUDP&sock=startd_1759196_0660> slot1@corona198.llnl.gov
09/27/24 09:36:28       Matched 3.0 haridev@corona198.llnl.gov <192.168.64.198:45159?addrs=192.168.64.198-45159&alias=corona198.llnl.gov&noUDP&sock=schedd_1945205_ba33> preempting none <192.168.64.198:45159?addrs=192.168.64.198-45159&alias=corona198.llnl.gov&noUDP&sock=startd_1945205_ba33> slot1@corona198.llnl.gov
09/27/24 09:49:15       Matched 6.0 haridev@corona198.llnl.gov <192.168.64.198:37555?addrs=192.168.64.198-37555&alias=corona198.llnl.gov&noUDP&sock=schedd_1950629_23e4> preempting none <192.168.64.198:37555?addrs=192.168.64.198-37555&alias=corona198.llnl.gov&noUDP&sock=startd_1950629_23e4> slot1@corona198.llnl.gov
09/27/24 09:58:27       Matched 10.0 haridev@corona198.llnl.gov <192.168.64.198:37555?addrs=192.168.64.198-37555&alias=corona198.llnl.gov&noUDP&sock=schedd_1950629_23e4> preempting none <192.168.64.198:37555?addrs=192.168.64.198-37555&alias=corona198.llnl.gov&noUDP&sock=startd_1950629_23e4> slot1@corona198.llnl.gov
09/27/24 10:48:00       Matched 16.0 haridev@corona266.llnl.gov <192.168.65.10:35377?addrs=192.168.65.10-35377&alias=corona266.llnl.gov&noUDP&sock=schedd_1367477_5f69> preempting none <192.168.65.10:35377?addrs=192.168.65.10-35377&alias=corona266.llnl.gov&noUDP&sock=startd_1367477_5f69> slot1@corona266.llnl.gov
09/27/24 10:56:03       Matched 21.0 haridev@corona268.llnl.gov <192.168.65.12:39065?addrs=192.168.65.12-39065&alias=corona268.llnl.gov&noUDP&sock=schedd_2158973_cb7d> preempting none <192.168.65.12:39065?addrs=192.168.65.12-39065&alias=corona268.llnl.gov&noUDP&sock=startd_2158973_cb7d> slot1@corona268.llnl.gov
09/27/24 11:02:26       Matched 25.0 haridev@corona268.llnl.gov <192.168.65.12:39065?addrs=192.168.65.12-39065&alias=corona268.llnl.gov&noUDP&sock=schedd_2158973_cb7d> preempting none <192.168.65.12:39065?addrs=192.168.65.12-39065&alias=corona268.llnl.gov&noUDP&sock=startd_2158973_cb7d> slot1@corona268.llnl.gov
09/27/24 11:25:15       Matched 36.0 haridev@corona230.llnl.gov <192.168.64.230:40855?addrs=192.168.64.230-40855&alias=corona230.llnl.gov&noUDP&sock=schedd_3746288_db91> preempting none <192.168.64.230:40855?addrs=192.168.64.230-40855&alias=corona230.llnl.gov&noUDP&sock=startd_3746288_db91> slot1@corona230.llnl.gov
09/27/24 11:32:02       Matched 40.0 haridev@corona230.llnl.gov <192.168.64.230:40855?addrs=192.168.64.230-40855&alias=corona230.llnl.gov&noUDP&sock=schedd_3746288_db91> preempting none <192.168.64.230:40855?addrs=192.168.64.230-40855&alias=corona230.llnl.gov&noUDP&sock=startd_3746288_db91> slot1@corona230.llnl.gov
09/27/24 12:10:24       Matched 46.0 haridev@corona192.llnl.gov <192.168.64.192:44501?addrs=192.168.64.192-44501&alias=corona192.llnl.gov&noUDP&sock=schedd_2561647_aa78> preempting none <192.168.64.192:44501?addrs=192.168.64.192-44501&alias=corona192.llnl.gov&noUDP&sock=startd_2561647_aa78> slot1@corona192.llnl.gov
09/27/24 12:17:36       Matched 50.0 haridev@corona192.llnl.gov <192.168.64.192:44501?addrs=192.168.64.192-44501&alias=corona192.llnl.gov&noUDP&sock=schedd_2561647_aa78> preempting none <192.168.64.192:44501?addrs=192.168.64.192-44501&alias=corona192.llnl.gov&noUDP&sock=startd_2561647_aa78> slot1@corona192.llnl.gov
